<?xml version="1.0" ?>
<!-- =================================================================================== -->
<!-- |    This document was autogenerated by xacro from melon.urdf.xacro               | -->
<!-- |    EDITING THIS FILE BY HAND IS NOT RECOMMENDED                                 | -->
<!-- =================================================================================== -->
<robot name="Melon">
  <material name="dark_blue">
    <color rgba="0.0 0.5 0.576 1.0"/>
  </material>
  <material name="black">
    <color rgba="0.0 0.0 0.0 1.0"/>
  </material>
  <material name="dark_black">
    <color rgba="0.1 0.1 0.1 1.0"/>
  </material>
  <material name="dark">
    <color rgba="0.3 0.3 0.3 1.0"/>
  </material>
  <material name="silver">
    <color rgba="0.700 0.700 0.700 1.000"/>
  </material>
  <material name="smokey_blue">
    <color rgba="0.25 0.31 0.33 1.00"/>
  </material>
  <material name="midnight_blue">
    <color rgba="0.10 0.15 0.17 1.0"/>
  </material>
  <material name="gray_blue">
    <color rgba="0.271 0.294 0.306 1.0"/>
  </material>
  <material name="ocean_blue">
    <color rgba="0.247 0.400 0.627 1.0"/>
  </material>
  <material name="charcoal">
    <color rgba="0.129 0.129 0.129 1.0"/>
  </material>
  <material name="steel_gray">
    <color rgba="0.325 0.376 0.392 1.0"/>
  </material>
  <!-- <xacro:include filename="$(find melon_description)/urdf/base_v2.gazebo.xacro" /> -->
  <!-- <xacro:base prefix=""/> -->
  <material name="aluminum">
    <color rgba="0.5 0.5 0.5 1"/>
  </material>
  <material name="plastic">
    <color rgba="0.1 0.1 0.1 1"/>
  </material>
  <!-- base -->
  <link name="base_footprint"/>
  <joint name="base_joint" type="fixed">
    <parent link="base_footprint"/>
    <child link="base_link"/>
    <origin rpy="0 0 0" xyz="0 0 0"/>
  </joint>
  <link name="base_link">
    <inertial>
      <origin rpy="0 0 1.57" xyz="0.01744420260337036 0.0763481410355218 0.4235647920657504"/>
      <mass value="50.0"/>
      <inertia ixx="16.050446" ixy="0.002034" ixz="0.007151" iyy="13.982493" iyz="-2.999695" izz="18.567703"/>
    </inertial>
    <!-- <visual>
        <origin xyz="0 0 0" rpy="0 0 1.57"/>
        <geometry>
          <mesh filename="package://melon_description/meshes/base_link.stl" scale="0.001 0.001 0.001"/>
        </geometry>
        <material name="silver"/>
      </visual>
      <collision>
        <origin xyz="0 0 0" rpy="0 0 1.57"/>
        <geometry>
          <mesh filename="package://melon_description/meshes/base_link.stl" scale="0.001 0.001 0.001"/>
        </geometry>
      </collision> -->
    <!-- body -->
    <visual>
      <origin rpy="0 0 1.57" xyz="-0.002 0.005 0.05"/>
      <geometry>
        <mesh filename="package://melon_description/meshes/body_1.stl" scale="0.001 0.001 0.001"/>
      </geometry>
      <material name="midnight_blue"/>
    </visual>
    <collision>
      <origin rpy="0 0 1.57" xyz="-0.002 0.005 0.05"/>
      <geometry>
        <mesh filename="package://melon_description/meshes/body_1.stl" scale="0.001 0.001 0.001"/>
      </geometry>
    </collision>
    <visual>
      <origin rpy="0 0 1.57" xyz="0.0075 0.678 0.069"/>
      <geometry>
        <mesh filename="package://melon_description/meshes/body_2.stl" scale="0.001 0.001 0.001"/>
      </geometry>
      <material name="dark_black"/>
    </visual>
    <collision>
      <origin rpy="0 0 1.57" xyz="0.0075 0.678 0.069"/>
      <geometry>
        <mesh filename="package://melon_description/meshes/body_2.stl" scale="0.001 0.001 0.001"/>
      </geometry>
    </collision>
    <visual>
      <origin rpy="0 0 -1.57" xyz="0.027 0.025 0.37"/>
      <geometry>
        <mesh filename="package://melon_description/meshes/body_3.stl" scale="0.001 0.001 0.001"/>
      </geometry>
      <material name="charcoal"/>
    </visual>
    <collision>
      <origin rpy="0 0 -1.57" xyz="0.027 0.025 0.37"/>
      <geometry>
        <mesh filename="package://melon_description/meshes/body_3.stl" scale="0.001 0.001 0.001"/>
      </geometry>
    </collision>
    <!-- caster mount -->
    <visual>
      <origin rpy="3.14 0 1.57" xyz="0.3 0.200 0.06"/>
      <geometry>
        <mesh filename="package://melon_description/meshes/ballfoint.stl" scale="0.001 0.001 0.001"/>
      </geometry>
      <material name="midnight_blue"/>
    </visual>
    <collision>
      <origin rpy="3.14 0 1.57" xyz="0.3 0.200 0.06"/>
      <geometry>
        <mesh filename="package://melon_description/meshes/ballfoint.stl" scale="0.001 0.001 0.001"/>
      </geometry>
    </collision>
    <visual>
      <origin rpy="3.14 0 1.57" xyz="0.3 -0.200 0.06"/>
      <geometry>
        <mesh filename="package://melon_description/meshes/ballfoint.stl" scale="0.001 0.001 0.001"/>
      </geometry>
      <material name="midnight_blue"/>
    </visual>
    <collision>
      <origin rpy="3.14 0 1.57" xyz="0.3 -0.200 0.06"/>
      <geometry>
        <mesh filename="package://melon_description/meshes/ballfoint.stl" scale="0.001 0.001 0.001"/>
      </geometry>
    </collision>
    <visual>
      <origin rpy="3.14 0 1.57" xyz="-0.33 0.200 0.06"/>
      <geometry>
        <mesh filename="package://melon_description/meshes/ballfoint.stl" scale="0.001 0.001 0.001"/>
      </geometry>
      <material name="midnight_blue"/>
    </visual>
    <collision>
      <origin rpy="3.14 0 1.57" xyz="-0.33 0.200 0.06"/>
      <geometry>
        <mesh filename="package://melon_description/meshes/ballfoint.stl" scale="0.001 0.001 0.001"/>
      </geometry>
    </collision>
    <visual>
      <origin rpy="3.14 0 1.57" xyz="-0.33 -0.200 0.06"/>
      <geometry>
        <mesh filename="package://melon_description/meshes/ballfoint.stl" scale="0.001 0.001 0.001"/>
      </geometry>
      <material name="midnight_blue"/>
    </visual>
    <collision>
      <origin rpy="3.14 0 1.57" xyz="-0.33 -0.200 0.06"/>
      <geometry>
        <mesh filename="package://melon_description/meshes/ballfoint.stl" scale="0.001 0.001 0.001"/>
      </geometry>
    </collision>
  </link>
  <!-- wheels -->
  <joint name="right_wheel_joint" type="continuous">
    <origin rpy="0 0 1.57" xyz="0.007002 -0.242002 0.10065"/>
    <parent link="base_link"/>
    <child link="right_wheel_1"/>
    <axis xyz="1.0 0.0 0.0"/>
    <dynamics damping="1.0"/>
  </joint>
  <link name="right_wheel_1">
    <inertial>
      <origin rpy="0 0 0" xyz="-0.020080456317257633 -2.190901024334141e-07 -9.838097278502822e-08"/>
      <mass value="0.5"/>
      <inertia ixx="0.005139" ixy="-0.0" ixz="-0.0" iyy="0.002706" iyz="0.0" izz="0.002706"/>
    </inertial>
    <visual>
      <origin rpy="0 0 0" xyz="0.242002 0.007002 -0.10065"/>
      <geometry>
        <mesh filename="package://melon_description/meshes/right_wheel_1.stl" scale="0.001 0.001 0.001"/>
      </geometry>
      <material name="dark"/>
    </visual>
    <collision>
      <origin rpy="0 1.57 0" xyz="-0.04 0.0 0.0"/>
      <geometry>
        <cylinder length="0.05" radius="0.10065"/>
      </geometry>
    </collision>
  </link>
  <joint name="left_wheel_joint" type="continuous">
    <origin rpy="0 0 1.57" xyz="0.007002 0.279998 0.10065"/>
    <parent link="base_link"/>
    <child link="left_wheel_1"/>
    <axis xyz="1.0 0.0 0.0"/>
    <dynamics damping="1.0"/>
  </joint>
  <link name="left_wheel_1">
    <inertial>
      <origin rpy="0 0 0" xyz="0.019919543682742402 -2.1909010231892234e-07 -9.838097249359468e-08"/>
      <mass value="0.5"/>
      <inertia ixx="0.005139" ixy="0.0" ixz="0.0" iyy="0.002706" iyz="0.0" izz="0.002706"/>
    </inertial>
    <visual>
      <origin rpy="0 0 0" xyz="-0.277998 0.007002 -0.10065"/>
      <geometry>
        <mesh filename="package://melon_description/meshes/left_wheel_1.stl" scale="0.001 0.001 0.001"/>
      </geometry>
      <material name="dark"/>
    </visual>
    <collision>
      <origin rpy="0 1.57 0" xyz="0.01 0.0 0.0"/>
      <geometry>
        <cylinder length="0.05" radius="0.10065"/>
      </geometry>
    </collision>
  </link>
  <!-- passive wheel -->
  <!-- front left -->
  <joint name="front_left_passive_wheel_x_frame_joint" type="continuous">
    <parent link="base_link"/>
    <child link="front_left_passive_wheel_x_frame"/>
    <axis xyz="1.0 0.0 0.0"/>
    <limit effort="1.0" velocity="3.0"/>
    <origin rpy="0 0 0" xyz="0.3 0.2 0.025"/>
    <dynamics damping="1.0"/>
  </joint>
  <link name="front_left_passive_wheel_x_frame">
    <inertial>
      <mass value="0.2"/>
      <origin xyz="0 0 0"/>
      <inertia ixx="0.001" ixy="0" ixz="0" iyy="0.001" iyz="0" izz="0.001"/>
    </inertial>
  </link>
  <joint name="front_left_passive_wheel_y_frame_joint" type="continuous">
    <parent link="front_left_passive_wheel_x_frame"/>
    <child link="front_left_passive_wheel_y_frame"/>
    <axis xyz="0.0 1.0 0.0"/>
    <limit effort="1.0" velocity="3.0"/>
    <origin rpy="0 0 0" xyz="0 0 0"/>
    <dynamics damping="1.0"/>
  </joint>
  <link name="front_left_passive_wheel_y_frame">
    <inertial>
      <mass value="0.2"/>
      <origin xyz="0 0 0"/>
      <inertia ixx="0.001" ixy="0" ixz="0" iyy="0.001" iyz="0" izz="0.001"/>
    </inertial>
  </link>
  <joint name="front_left_passive_wheel_z_frame_joint" type="continuous">
    <parent link="front_left_passive_wheel_y_frame"/>
    <child link="front_left_passive_wheel_z_link"/>
    <axis xyz="0.0 0.0 1.0"/>
    <limit effort="1.0" velocity="3.0"/>
    <origin rpy="0 0 0" xyz="0 0 0"/>
    <dynamics damping="1.0"/>
  </joint>
  <link name="front_left_passive_wheel_z_link">
    <visual>
      <geometry>
        <sphere radius="0.025"/>
      </geometry>
      <material name="dark"/>
    </visual>
    <collision>
      <geometry>
        <sphere radius="0.025"/>
      </geometry>
    </collision>
    <inertial>
      <mass value="0.2"/>
      <origin xyz="0 0 0"/>
      <inertia ixx="0.001" ixy="0" ixz="0" iyy="0.001" iyz="0" izz="0.001"/>
    </inertial>
  </link>
  <!-- front right -->
  <joint name="front_right_passive_wheel_x_frame_joint" type="continuous">
    <parent link="base_link"/>
    <child link="front_right_passive_wheel_x_frame"/>
    <axis xyz="1.0 0.0 0.0"/>
    <limit effort="1.0" velocity="3.0"/>
    <origin rpy="0 0 0" xyz="0.3 -0.2 0.025"/>
    <dynamics damping="1.0"/>
  </joint>
  <link name="front_right_passive_wheel_x_frame">
    <inertial>
      <mass value="0.2"/>
      <origin xyz="0 0 0"/>
      <inertia ixx="0.001" ixy="0" ixz="0" iyy="0.001" iyz="0" izz="0.001"/>
    </inertial>
  </link>
  <joint name="front_right_passive_wheel_y_frame_joint" type="continuous">
    <parent link="front_right_passive_wheel_x_frame"/>
    <child link="front_right_passive_wheel_y_frame"/>
    <axis xyz="0.0 1.0 0.0"/>
    <limit effort="1.0" velocity="3.0"/>
    <origin rpy="0 0 0" xyz="0 0 0"/>
    <dynamics damping="1.0"/>
  </joint>
  <link name="front_right_passive_wheel_y_frame">
    <inertial>
      <mass value="0.2"/>
      <origin xyz="0 0 0"/>
      <inertia ixx="0.001" ixy="0" ixz="0" iyy="0.001" iyz="0" izz="0.001"/>
    </inertial>
  </link>
  <joint name="front_right_passive_wheel_z_frame_joint" type="continuous">
    <parent link="front_right_passive_wheel_y_frame"/>
    <child link="front_right_passive_wheel_z_link"/>
    <axis xyz="0.0 0.0 1.0"/>
    <limit effort="1.0" velocity="3.0"/>
    <origin rpy="0 0 0" xyz="0 0 0"/>
    <dynamics damping="1.0"/>
  </joint>
  <link name="front_right_passive_wheel_z_link">
    <visual>
      <geometry>
        <sphere radius="0.025"/>
      </geometry>
      <material name="dark"/>
    </visual>
    <collision>
      <geometry>
        <sphere radius="0.025"/>
      </geometry>
    </collision>
    <inertial>
      <mass value="0.2"/>
      <origin xyz="0 0 0"/>
      <inertia ixx="0.001" ixy="0" ixz="0" iyy="0.001" iyz="0" izz="0.001"/>
    </inertial>
  </link>
  <!-- back left-->
  <joint name="back_left_passive_wheel_x_frame_joint" type="continuous">
    <parent link="base_link"/>
    <child link="back_left_passive_wheel_x_frame"/>
    <axis xyz="1.0 0.0 0.0"/>
    <limit effort="1.0" velocity="3.0"/>
    <origin rpy="0 0 0" xyz="-0.33 0.2 0.025"/>
    <dynamics damping="1.0"/>
  </joint>
  <link name="back_left_passive_wheel_x_frame">
    <inertial>
      <mass value="0.2"/>
      <origin xyz="0 0 0"/>
      <inertia ixx="0.001" ixy="0" ixz="0" iyy="0.001" iyz="0" izz="0.001"/>
    </inertial>
  </link>
  <joint name="back_left_passive_wheel_y_frame_joint" type="continuous">
    <parent link="back_left_passive_wheel_x_frame"/>
    <child link="back_left_passive_wheel_y_frame"/>
    <axis xyz="0.0 1.0 0.0"/>
    <limit effort="1.0" velocity="3.0"/>
    <origin rpy="0 0 0" xyz="0 0 0"/>
    <dynamics damping="1.0"/>
  </joint>
  <link name="back_left_passive_wheel_y_frame">
    <inertial>
      <mass value="0.2"/>
      <origin xyz="0 0 0"/>
      <inertia ixx="0.001" ixy="0" ixz="0" iyy="0.001" iyz="0" izz="0.001"/>
    </inertial>
  </link>
  <joint name="back_left_passive_wheel_z_frame_joint" type="continuous">
    <parent link="back_left_passive_wheel_y_frame"/>
    <child link="back_left_passive_wheel_z_link"/>
    <axis xyz="0.0 0.0 1.0"/>
    <limit effort="1.0" velocity="3.0"/>
    <origin rpy="0 0 0" xyz="0 0 0"/>
    <dynamics damping="1.0"/>
  </joint>
  <link name="back_left_passive_wheel_z_link">
    <visual>
      <geometry>
        <sphere radius="0.025"/>
      </geometry>
      <material name="dark"/>
    </visual>
    <collision>
      <geometry>
        <sphere radius="0.025"/>
      </geometry>
    </collision>
    <inertial>
      <mass value="0.2"/>
      <origin xyz="0 0 0"/>
      <inertia ixx="0.001" ixy="0" ixz="0" iyy="0.001" iyz="0" izz="0.001"/>
    </inertial>
  </link>
  <!-- back right-->
  <joint name="back_right_passive_wheel_x_frame_joint" type="continuous">
    <parent link="base_link"/>
    <child link="back_right_passive_wheel_x_frame"/>
    <axis xyz="1.0 0.0 0.0"/>
    <limit effort="1.0" velocity="3.0"/>
    <origin rpy="0 0 0" xyz="-0.33 -0.2 0.025"/>
    <dynamics damping="1.0"/>
  </joint>
  <link name="back_right_passive_wheel_x_frame">
    <inertial>
      <mass value="0.2"/>
      <origin xyz="0 0 0"/>
      <inertia ixx="0.001" ixy="0" ixz="0" iyy="0.001" iyz="0" izz="0.001"/>
    </inertial>
  </link>
  <joint name="back_right_passive_wheel_y_frame_joint" type="continuous">
    <parent link="back_right_passive_wheel_x_frame"/>
    <child link="back_right_passive_wheel_y_frame"/>
    <axis xyz="0.0 1.0 0.0"/>
    <limit effort="1.0" velocity="3.0"/>
    <origin rpy="0 0 0" xyz="0 0 0"/>
    <dynamics damping="1.0"/>
  </joint>
  <link name="back_right_passive_wheel_y_frame">
    <inertial>
      <mass value="0.2"/>
      <origin xyz="0 0 0"/>
      <inertia ixx="0.001" ixy="0" ixz="0" iyy="0.001" iyz="0" izz="0.001"/>
    </inertial>
  </link>
  <joint name="back_right_passive_wheel_z_frame_joint" type="continuous">
    <parent link="back_right_passive_wheel_y_frame"/>
    <child link="back_right_passive_wheel_z_link"/>
    <axis xyz="0.0 0.0 1.0"/>
    <limit effort="1.0" velocity="3.0"/>
    <origin rpy="0 0 0" xyz="0 0 0"/>
    <dynamics damping="1.0"/>
  </joint>
  <link name="back_right_passive_wheel_z_link">
    <visual>
      <geometry>
        <sphere radius="0.025"/>
      </geometry>
      <material name="dark"/>
    </visual>
    <collision>
      <geometry>
        <sphere radius="0.025"/>
      </geometry>
    </collision>
    <inertial>
      <mass value="0.2"/>
      <origin xyz="0 0 0"/>
      <inertia ixx="0.001" ixy="0" ixz="0" iyy="0.001" iyz="0" izz="0.001"/>
    </inertial>
  </link>
  <!-- base_scan -->
  <joint name="base_scan_joint" type="fixed">
    <parent link="base_link"/>
    <child link="base_scan"/>
    <origin rpy="0 0 0" xyz="0.28 0  0.125"/>
  </joint>
  <link name="base_scan">
    <inertial>
      <origin rpy="0 0 0" xyz="0 0 0"/>
      <mass value="0.25"/>
      <inertia ixx="0.0001" ixy="0.0" ixz="0.0" iyy="0.0001" iyz="0.0" izz="0.0001"/>
    </inertial>
    <visual>
      <origin rpy="0 0 0" xyz="0 0.28 -0.125"/>
      <geometry>
        <mesh filename="package://melon_description/meshes/lider_1.stl" scale="0.001 0.001 0.001"/>
      </geometry>
      <material name="black"/>
    </visual>
    <collision>
      <origin rpy="0 0 0" xyz="0 0 0"/>
      <geometry>
        <cylinder length="0.05" radius="0.05"/>
      </geometry>
    </collision>
    <visual>
      <origin rpy="0 0 0" xyz="0 0 -0.02"/>
      <geometry>
        <box size="0.11 0.11 0.02"/>
      </geometry>
      <material name="charcoal"/>
    </visual>
    <collision>
      <origin rpy="0 0 0" xyz="0 0 -0.02"/>
      <geometry>
        <box size="0.11 0.11 0.02"/>
      </geometry>
    </collision>
  </link>
  <!-- mount -->
  <link name="mid_mount"/>
  <joint name="mid_mount_joint" type="fixed">
    <parent link="base_link"/>
    <child link="mid_mount"/>
    <origin rpy="0 0 1.57" xyz="0.3 0 0.765"/>
  </joint>
  <!-- safety_distance: Minimum safety distance in [m] by which the collision volumes are expanded and which is enforced during robot motions -->
  <!-- arm_id: Namespace of the robot arm. Serves to differentiate between arms in case of multiple instances. -->
  <!-- joint_limits: description of the joint limits that comes from a YAML file. Example definition: ${xacro.load_yaml('$(find franka_description)/robots/fr3/joint_limits.yaml')} -->
  <!-- kinematics: description of the kinematics that comes from a YAML file. Example definition: ${xacro.load_yaml('$(find franka_description)/robots/fr3/kinematics.yaml')} -->
  <!-- inertials: description of the inertials that comes from a YAML file. Example definition: ${xacro.load_yaml('$(find franka_description)/robots/fr3/inertials.yaml')} -->
  <!-- dynamics: description of the dynamics that comes from a YAML file. Example definition: ${xacro.load_yaml('$(find franka_description)/robots/fr3/dynamics.yaml')} -->
  <!-- sub-link defining detailed meshes for collision with environment -->
  <link name="fr3_link0">
    <visual name="fr3_link0_visual">
      <geometry>
        <mesh filename="package://franka_description/meshes/robot_arms/fr3/visual/link0.dae"/>
      </geometry>
    </visual>
    <collision name="fr3_link0_collision">
      <geometry>
        <mesh filename="package://franka_description/meshes/robot_arms/fr3/collision/link0.stl"/>
      </geometry>
    </collision>
    <inertial>
      <origin rpy="0 0 0" xyz="-0.0172 0.0004 0.0745"/>
      <mass value="2.3966"/>
      <inertia ixx="0.009" ixy="0.0" ixz="0.002" iyy="0.0115" iyz="0.0" izz="0.0085"/>
    </inertial>
  </link>
  <!-- sub-link defining detailed meshes for collision with environment -->
  <link name="fr3_link1">
    <visual name="fr3_link1_visual">
      <geometry>
        <mesh filename="package://franka_description/meshes/robot_arms/fr3/visual/link1.dae"/>
      </geometry>
    </visual>
    <collision name="fr3_link1_collision">
      <geometry>
        <mesh filename="package://franka_description/meshes/robot_arms/fr3/collision/link1.stl"/>
      </geometry>
    </collision>
    <inertial>
      <origin rpy="0 0 0" xyz="0.0000004128 -0.0181251324 -0.0386035970"/>
      <mass value="2.9274653454"/>
      <inertia ixx="0.023927316485107913" ixy="1.3317903455714081e-05" ixz="-0.00011404774918616684" iyy="0.0224821613275756" iyz="-0.0019950320628240115" izz="0.006350098258530016"/>
    </inertial>
  </link>
  <joint name="fr3_joint1" type="revolute">
    <origin rpy="0 0 0" xyz="0 0 0.333"/>
    <parent link="fr3_link0"/>
    <child link="fr3_link1"/>
    <axis xyz="0 0 1"/>
    <limit effort="87.0" lower="-2.7437" upper="2.7437" velocity="2.62"/>
    <safety_controller k_position="100.0" k_velocity="40.0" soft_lower_limit="-2.7437" soft_upper_limit="2.7437"/>
    <dynamics D="1" K="7000" damping="0.003" friction="0.2" mu_coulomb="0" mu_viscous="16"/>
  </joint>
  <!-- sub-link defining detailed meshes for collision with environment -->
  <link name="fr3_link2">
    <visual name="fr3_link2_visual">
      <geometry>
        <mesh filename="package://franka_description/meshes/robot_arms/fr3/visual/link2.dae"/>
      </geometry>
    </visual>
    <collision name="fr3_link2_collision">
      <geometry>
        <mesh filename="package://franka_description/meshes/robot_arms/fr3/collision/link2.stl"/>
      </geometry>
    </collision>
    <inertial>
      <origin rpy="0 0 0" xyz="0.0031828864 -0.0743221644 0.0088146084"/>
      <mass value="2.9355370338"/>
      <inertia ixx="0.041938946257609425" ixy="0.00020257331521090626" ixz="0.004077784227179924" iyy="0.02514514885014724" iyz="-0.0042252158006570156" izz="0.06170214472888839"/>
    </inertial>
  </link>
  <joint name="fr3_joint2" type="revolute">
    <origin rpy="-1.570796326794897 0 0" xyz="0 0 0"/>
    <parent link="fr3_link1"/>
    <child link="fr3_link2"/>
    <axis xyz="0 0 1"/>
    <limit effort="87.0" lower="-1.7837" upper="1.7837" velocity="2.62"/>
    <safety_controller k_position="100.0" k_velocity="40.0" soft_lower_limit="-1.7837" soft_upper_limit="1.7837"/>
    <dynamics D="1" K="7000" damping="0.003" friction="0.2" mu_coulomb="0" mu_viscous="16"/>
  </joint>
  <!-- sub-link defining detailed meshes for collision with environment -->
  <link name="fr3_link3">
    <visual name="fr3_link3_visual">
      <geometry>
        <mesh filename="package://franka_description/meshes/robot_arms/fr3/visual/link3.dae"/>
      </geometry>
    </visual>
    <collision name="fr3_link3_collision">
      <geometry>
        <mesh filename="package://franka_description/meshes/robot_arms/fr3/collision/link3.stl"/>
      </geometry>
    </collision>
    <inertial>
      <origin rpy="0 0 0" xyz="0.0407015686 -0.0048200565 -0.0289730823"/>
      <mass value="2.2449013699"/>
      <inertia ixx="0.02410142547240885" ixy="0.002404694559042109" ixz="-0.002856269270114313" iyy="0.01974053266708178" iyz="-0.002104212683891874" izz="0.019044494482244823"/>
    </inertial>
  </link>
  <joint name="fr3_joint3" type="revolute">
    <origin rpy="1.570796326794897 0 0" xyz="0 -0.316 0"/>
    <parent link="fr3_link2"/>
    <child link="fr3_link3"/>
    <axis xyz="0 0 1"/>
    <limit effort="87.0" lower="-2.9007" upper="2.9007" velocity="2.62"/>
    <safety_controller k_position="100.0" k_velocity="40.0" soft_lower_limit="-2.9007" soft_upper_limit="2.9007"/>
    <dynamics D="1" K="7000" damping="0.003" friction="0.2" mu_coulomb="0" mu_viscous="16"/>
  </joint>
  <!-- sub-link defining detailed meshes for collision with environment -->
  <link name="fr3_link4">
    <visual name="fr3_link4_visual">
      <geometry>
        <mesh filename="package://franka_description/meshes/robot_arms/fr3/visual/link4.dae"/>
      </geometry>
    </visual>
    <collision name="fr3_link4_collision">
      <geometry>
        <mesh filename="package://franka_description/meshes/robot_arms/fr3/collision/link4.stl"/>
      </geometry>
    </collision>
    <inertial>
      <origin rpy="0 0 0" xyz="-0.0459100965 0.0630492960 -0.0085187868"/>
      <mass value="2.6155955791"/>
      <inertia ixx="0.03452998321913202" ixy="0.01322552265982813" ixz="0.01015142998484113" iyy="0.028881621933049058" iyz="-0.0009762833870704552" izz="0.04125471171146641"/>
    </inertial>
  </link>
  <joint name="fr3_joint4" type="revolute">
    <origin rpy="1.570796326794897 0 0" xyz="0.0825 0 0"/>
    <parent link="fr3_link3"/>
    <child link="fr3_link4"/>
    <axis xyz="0 0 1"/>
    <limit effort="87.0" lower="-3.0421" upper="-0.1518" velocity="2.62"/>
    <safety_controller k_position="100.0" k_velocity="40.0" soft_lower_limit="-3.0421" soft_upper_limit="-0.1518"/>
    <dynamics D="1" K="7000" damping="0.003" friction="0.2" mu_coulomb="0" mu_viscous="16"/>
  </joint>
  <!-- sub-link defining detailed meshes for collision with environment -->
  <link name="fr3_link5">
    <visual name="fr3_link5_visual">
      <geometry>
        <mesh filename="package://franka_description/meshes/robot_arms/fr3/visual/link5.dae"/>
      </geometry>
    </visual>
    <collision name="fr3_link5_collision">
      <geometry>
        <mesh filename="package://franka_description/meshes/robot_arms/fr3/collision/link5.stl"/>
      </geometry>
    </collision>
    <inertial>
      <origin rpy="0 0 0" xyz="-0.0016039605 0.0292536262 -0.0972965990"/>
      <mass value="2.3271207594"/>
      <inertia ixx="0.051610278463662895" ixy="-0.005715173387783472" ixz="-0.0035673167625872135" iyy="0.04787729713371481" iyz="0.010673985108535986" izz="0.016423625579357254"/>
    </inertial>
  </link>
  <joint name="fr3_joint5" type="revolute">
    <origin rpy="-1.570796326794897 0 0" xyz="-0.0825 0.384 0"/>
    <parent link="fr3_link4"/>
    <child link="fr3_link5"/>
    <axis xyz="0 0 1"/>
    <limit effort="12.0" lower="-2.8065" upper="2.8065" velocity="5.26"/>
    <safety_controller k_position="100.0" k_velocity="40.0" soft_lower_limit="-2.8065" soft_upper_limit="2.8065"/>
    <dynamics D="1" K="7000" damping="0.003" friction="0.2" mu_coulomb="0" mu_viscous="16"/>
  </joint>
  <!-- sub-link defining detailed meshes for collision with environment -->
  <link name="fr3_link6">
    <visual name="fr3_link6_visual">
      <geometry>
        <mesh filename="package://franka_description/meshes/robot_arms/fr3/visual/link6.dae"/>
      </geometry>
    </visual>
    <collision name="fr3_link6_collision">
      <geometry>
        <mesh filename="package://franka_description/meshes/robot_arms/fr3/collision/link6.stl"/>
      </geometry>
    </collision>
    <inertial>
      <origin rpy="0 0 0" xyz="0.0597131221 -0.0410294666 -0.0101692726"/>
      <mass value="1.8170376524"/>
      <inertia ixx="0.005412333594383447" ixy="0.006193456360285834" ixz="0.0014219289306117652" iyy="0.014058329545509979" iyz="-0.0013140753741120031" izz="0.016080817924212554"/>
    </inertial>
  </link>
  <joint name="fr3_joint6" type="revolute">
    <origin rpy="1.570796326794897 0 0" xyz="0 0 0"/>
    <parent link="fr3_link5"/>
    <child link="fr3_link6"/>
    <axis xyz="0 0 1"/>
    <limit effort="12.0" lower="0.5445" upper="4.5169" velocity="4.18"/>
    <safety_controller k_position="100.0" k_velocity="40.0" soft_lower_limit="0.5445" soft_upper_limit="4.5169"/>
    <dynamics D="1" K="7000" damping="0.003" friction="0.2" mu_coulomb="0" mu_viscous="16"/>
  </joint>
  <!-- sub-link defining detailed meshes for collision with environment -->
  <link name="fr3_link7">
    <visual name="fr3_link7_visual">
      <geometry>
        <mesh filename="package://franka_description/meshes/robot_arms/fr3/visual/link7.dae"/>
      </geometry>
    </visual>
    <collision name="fr3_link7_collision">
      <geometry>
        <mesh filename="package://franka_description/meshes/robot_arms/fr3/collision/link7.stl"/>
      </geometry>
    </collision>
    <inertial>
      <origin rpy="0 0 0" xyz="0.0045225817 0.0086261921 -0.0161633251"/>
      <mass value="0.6271432862"/>
      <inertia ixx="0.00021092389150104718" ixy="-2.433299114461931e-05" ixz="4.564480393778983e-05" iyy="0.00017718568002411474" iyz="8.744070223226438e-05" izz="5.993190599659971e-05"/>
    </inertial>
  </link>
  <joint name="fr3_joint7" type="revolute">
    <origin rpy="1.570796326794897 0 0" xyz="0.088 0 0"/>
    <parent link="fr3_link6"/>
    <child link="fr3_link7"/>
    <axis xyz="0 0 1"/>
    <limit effort="12.0" lower="-3.0159" upper="3.0159" velocity="5.26"/>
    <safety_controller k_position="100.0" k_velocity="40.0" soft_lower_limit="-3.0159" soft_upper_limit="3.0159"/>
    <dynamics D="1" K="7000" damping="0.003" friction="0.2" mu_coulomb="0" mu_viscous="16"/>
  </joint>
  <link name="fr3_link8"/>
  <joint name="fr3_joint8" type="fixed">
    <origin rpy="0 0 0" xyz="0 0 0.107"/>
    <parent link="fr3_link7"/>
    <child link="fr3_link8"/>
  </joint>
  <joint name="fr3_hand_joint" type="fixed">
    <parent link="fr3_link8"/>
    <child link="fr3_hand"/>
    <origin rpy="0 0 -0.7853981633974483" xyz="0 0 0"/>
  </joint>
  <!-- sub-link defining detailed meshes for collision with environment -->
  <link name="fr3_hand">
    <visual name="fr3_hand_visual">
      <geometry>
        <mesh filename="package://franka_description/meshes/robot_ee/franka_hand_white/visual/hand.dae"/>
      </geometry>
    </visual>
    <collision name="fr3_hand_collision">
      <geometry>
        <mesh filename="package://franka_description/meshes/robot_ee/franka_hand_white/collision/hand.stl"/>
      </geometry>
    </collision>
    <inertial>
      <origin rpy="0 0 0" xyz="-0.0000376 0.0119128 0.0207260"/>
      <mass value="0.6544"/>
      <inertia ixx="0.00186" ixy="0.0" ixz="0.0" iyy="0.0003" iyz="-2e-05" izz="0.00174"/>
    </inertial>
  </link>
  <!-- Define the hand_tcp frame -->
  <link name="fr3_hand_tcp"/>
  <joint name="fr3_hand_tcp_joint" type="fixed">
    <origin rpy="0 0 0" xyz="0 0 0.1034"/>
    <parent link="fr3_hand"/>
    <child link="fr3_hand_tcp"/>
  </joint>
  <link name="fr3_leftfinger">
    <visual name="fr3_leftfinger_visual">
      <geometry>
        <mesh filename="package://franka_description/meshes/robot_ee/franka_hand_white/visual/finger.dae"/>
      </geometry>
    </visual>
    <!-- screw mount -->
    <collision>
      <origin rpy="0 0 0" xyz="0 18.5e-3 11e-3"/>
      <geometry>
        <box size="22e-3 15e-3 20e-3"/>
      </geometry>
    </collision>
    <!-- cartriage sledge -->
    <collision>
      <origin rpy="0 0 0" xyz="0 6.8e-3 2.2e-3"/>
      <geometry>
        <box size="22e-3 8.8e-3 3.8e-3"/>
      </geometry>
    </collision>
    <!-- diagonal finger -->
    <collision>
      <origin rpy="0.5235987755982988 0 0" xyz="0 15.9e-3 28.35e-3"/>
      <geometry>
        <box size="17.5e-3 7e-3 23.5e-3"/>
      </geometry>
    </collision>
    <!-- rubber tip with which to grasp -->
    <collision>
      <origin rpy="0 0 0" xyz="0 7.58e-3 45.25e-3"/>
      <geometry>
        <box size="17.5e-3 15.2e-3 18.5e-3"/>
      </geometry>
    </collision>
    <inertial>
      <origin rpy="0 0 0" xyz="0 0.0152850 0.0219675"/>
      <mass value="0.0291"/>
      <inertia ixx="8.49e-06" ixy="0.0" ixz="0.0" iyy="8.53e-06" iyz="-1.06e-06" izz="1.77e-06"/>
    </inertial>
  </link>
  <link name="fr3_rightfinger">
    <visual name="fr3_rightfinger_visual">
      <origin rpy="0 0 0" xyz="0 0 0"/>
      <geometry>
        <mesh filename="package://franka_description/meshes/robot_ee/franka_hand_white/visual/finger.dae"/>
      </geometry>
    </visual>
    <!-- screw mount -->
    <collision>
      <origin rpy="0 0 0" xyz="0 18.5e-3 11e-3"/>
      <geometry>
        <box size="22e-3 15e-3 20e-3"/>
      </geometry>
    </collision>
    <!-- cartriage sledge -->
    <collision>
      <origin rpy="0 0 0" xyz="0 6.8e-3 2.2e-3"/>
      <geometry>
        <box size="22e-3 8.8e-3 3.8e-3"/>
      </geometry>
    </collision>
    <!-- diagonal finger -->
    <collision>
      <origin rpy="-0.5235987755982988 0 3.141592653589793" xyz="0 15.9e-3 28.35e-3"/>
      <geometry>
        <box size="17.5e-3 7e-3 23.5e-3"/>
      </geometry>
    </collision>
    <!-- rubber tip with which to grasp -->
    <collision>
      <origin rpy="0 0 0" xyz="0 7.58e-3 45.25e-3"/>
      <geometry>
        <box size="17.5e-3 15.2e-3 18.5e-3"/>
      </geometry>
    </collision>
    <inertial>
      <origin rpy="0 0 0" xyz="0 0.0152850 0.0219675"/>
      <mass value="0.0291"/>
      <inertia ixx="8.49e-06" ixy="0.0" ixz="0.0" iyy="8.53e-06" iyz="-1.06e-06" izz="1.77e-06"/>
    </inertial>
  </link>
  <joint name="fr3_finger_joint1" type="prismatic">
    <parent link="fr3_hand"/>
    <child link="fr3_leftfinger"/>
    <origin rpy="0 0 0" xyz="0 0 0.0584"/>
    <axis xyz="0 1 0"/>
    <limit effort="100" lower="0.0" upper="0.04" velocity="0.2"/>
    <dynamics damping="0.3"/>
  </joint>
  <joint name="fr3_finger_joint2" type="prismatic">
    <parent link="fr3_hand"/>
    <child link="fr3_rightfinger"/>
    <origin rpy="0 0 3.141592653589793" xyz="0 0 0.0584"/>
    <axis xyz="0 1 0"/>
    <limit effort="100" lower="0.0" upper="0.04" velocity="0.2"/>
    <mimic joint="fr3_finger_joint1"/>
    <dynamics damping="0.3"/>
  </joint>
  <!-- camera body, with origin at bottom screw mount -->
  <joint name="camera_joint" type="fixed">
    <origin rpy="0 -1.57 3.14" xyz="0.017 0.0 0.035"/>
    <parent link="fr3_hand"/>
    <child link="camera_bottom_screw_frame"/>
  </joint>
  <link name="camera_bottom_screw_frame"/>
  <joint name="camera_link_joint" type="fixed">
    <origin rpy="0 0 0" xyz="0.010600000000000002 0.0175 0.0125"/>
    <parent link="camera_bottom_screw_frame"/>
    <child link="camera_link"/>
  </joint>
  <link name="camera_link">
    <visual>
      <!-- the mesh origin is at front plate in between the two infrared camera axes -->
      <origin rpy="1.5707963267948966 0 1.5707963267948966" xyz="0.0043 -0.0175 0"/>
      <geometry>
        <mesh filename="file:///opt/ros/humble/share/realsense2_description/meshes/d435.dae"/>
      </geometry>
    </visual>
    <collision>
      <origin rpy="0 0 0" xyz="0 -0.0175 0"/>
      <geometry>
        <box size="0.02505 0.09 0.025"/>
      </geometry>
    </collision>
    <inertial>
      <!-- The following are not reliable values, and should not be used for modeling -->
      <mass value="0.072"/>
      <origin xyz="0 0 0"/>
      <inertia ixx="0.003881243" ixy="0.0" ixz="0.0" iyy="0.000498940" iyz="0.0" izz="0.003879257"/>
    </inertial>
  </link>
  <!-- camera depth joints and links -->
  <joint name="camera_depth_joint" type="fixed">
    <origin rpy="0 0 0" xyz="0 0 0"/>
    <parent link="camera_link"/>
    <child link="camera_depth_frame"/>
  </joint>
  <link name="camera_depth_frame"/>
  <joint name="camera_depth_optical_joint" type="fixed">
    <origin rpy="-1.5707963267948966 0 -1.5707963267948966" xyz="0 0 0"/>
    <parent link="camera_depth_frame"/>
    <child link="camera_depth_optical_frame"/>
  </joint>
  <link name="camera_depth_optical_frame"/>
  <!-- camera left IR joints and links -->
  <joint name="camera_infra1_joint" type="fixed">
    <origin rpy="0 0 0" xyz="0 0.0 0"/>
    <parent link="camera_link"/>
    <child link="camera_infra1_frame"/>
  </joint>
  <link name="camera_infra1_frame"/>
  <joint name="camera_infra1_optical_joint" type="fixed">
    <origin rpy="-1.5707963267948966 0 -1.5707963267948966" xyz="0 0 0"/>
    <parent link="camera_infra1_frame"/>
    <child link="camera_infra1_optical_frame"/>
  </joint>
  <link name="camera_infra1_optical_frame"/>
  <!-- camera right IR joints and links -->
  <joint name="camera_infra2_joint" type="fixed">
    <origin rpy="0 0 0" xyz="0 -0.05 0"/>
    <parent link="camera_link"/>
    <child link="camera_infra2_frame"/>
  </joint>
  <link name="camera_infra2_frame"/>
  <joint name="camera_infra2_optical_joint" type="fixed">
    <origin rpy="-1.5707963267948966 0 -1.5707963267948966" xyz="0 0 0"/>
    <parent link="camera_infra2_frame"/>
    <child link="camera_infra2_optical_frame"/>
  </joint>
  <link name="camera_infra2_optical_frame"/>
  <!-- camera color joints and links -->
  <joint name="camera_color_joint" type="fixed">
    <origin rpy="0 0 0" xyz="0 0.015 0"/>
    <parent link="camera_link"/>
    <child link="camera_color_frame"/>
  </joint>
  <link name="camera_color_frame"/>
  <joint name="camera_color_optical_joint" type="fixed">
    <origin rpy="-1.5707963267948966 0 -1.5707963267948966" xyz="0 0 0"/>
    <parent link="camera_color_frame"/>
    <child link="camera_color_optical_frame"/>
  </joint>
  <link name="camera_color_optical_frame"/>
  <joint name="mid_mount_fixed" type="fixed">
    <parent link="mid_mount"/>
    <child link="fr3_link0"/>
    <origin rpy="0 0 -1.57" xyz="0 0 0"/>
  </joint>
</robot>
